Workbook
Name Bahnhof: '[1]Techn. Übergangsuntersuchung'!#REF!
Name Bahnhof: 'WU Protokoll'!$R$7
Name Bahnhof: '[1]Techn. Übergangsuntersuchung'!#REF!
Name Sendungs_Nr.: #REF!
Name Sendungs_Nr.: #REF!
Name Sendungs_Nr.: #REF!

Sheet Wagenliste
A1: Wagenliste (Wg und nicht arbeitende Tfz) | M1: Zugnummer | P1: Gültig ab Bahnhof: | U1: Gültig bis Bahnhof:
P2: EGBK | U2: Schkeuditz Luftfracht
A4: 45 | B4: 46 | G4: 47 | H4: 48 | I4: 49 | J4: 50 | K4: 51 | L4: 52 | N4: 53 | O4: 54 | P4: 55 | S4: 56 | T4: 57 | U4: 58 | V4: 59 | W4: 60
A5: Pos. | B5: Nummer | G5: Anzahl Radsätze | H5: Länge über Puffer (m) | I5: Ladungs-gewicht (t) | J5: Gesamt-gewicht (t) | K5: Brems-sohlentyp | L5: Brems­ gewicht (t) | N5: wirksame Bremsen | O5: Fest-halte-kraft Hbr (kN) | P5: RID | S5: außergewöhnl. Sendung | T5: Zielbahnhof | U5: V Max km/h | V5: erforderliche Streckenklasse | W5: Bemerkungen
B6: 1-2 | C6: 3-4 | D6: 5-7 | E6: 9-11 | F6: 12 | L6: P | M6: G | P6: Gef. Nr | Q6: UN Nr | R6: Gef. Zettel | X6: Prüfziffer
A7: 1 | B7: 378078308871 | G7: 4 | H7: 16.4 | I7: 66.3 | J7: 89.2 | K7: K | M7: 59 | N7: =L7+M7 -> 59 | O7: 20.2 | P7: 30 | Q7: 1863 | R7: 3 | S7: 0 | T7: =IF(ISBLANK($B7),"",$U$2) -> Schkeuditz Luftfracht | U7: 100 | V7: D | W7: H | X7: ='Formeln Rdx'!AN7 -> 0 | Y7: =IF($K7="L","OK",IF(K7="K","OK",IF(K7="LL","OK","NOK"))) -> OK | Z7: =IF(OR(N7=4,N7="-"),"OK","NOK") -> NOK
A8: 2 | B8: 378078430758 | G8: 4 | H8: 16.4 | K8: K | M8: 60 | N8: =L8+M8 -> 60 | O8: 23.9 | P8: 30 | Q8: 1863 | R8: 3 | S8: 0 | T8: =IF(ISBLANK($B8),"",$U$2) -> Schkeuditz Luftfracht | U8: 100 | V8: D | W8: H | X8: ='Formeln Rdx'!AN8 -> 0 | Y8: =IF($K8="L","OK",IF(K8="K","OK",IF(K8="LL","OK","NOK"))) -> OK | Z8: =IF(OR(N8=4,N8="-"),"OK","NOK") -> NOK
A9: 3 | B9: 378078430659 | G9: 4 | H9: 16.4 | K9: K | M9: 60 | N9: =L9+M9 -> 60 | O9: 23.8 | P9: 30 | Q9: 1863 | R9: 3 | S9: 0 | T9: =IF(ISBLANK($B9),"",$U$2) -> Schkeuditz Luftfracht | U9: 100 | V9: D | W9: H | X9: ='Formeln Rdx'!AN9 -> 0 | Y9: =IF($K9="L","OK",IF(K9="K","OK",IF(K9="LL","OK","NOK"))) -> OK | Z9: =IF(OR(N9=4,N9="-"),"OK","NOK") -> NOK
A10: 4 | B10: 378478296361 | G10: 4 | H10: 16.69 | K10: K | M10: 59 | N10: =L10+M10 -> 59 | O10: 22.1 | P10: 30 | Q10: 1863 | R10: 3 | S10: 0 | T10: =IF(ISBLANK($B10),"",$U$2) -> Schkeuditz Luftfracht | U10: 100 | V10: D | W10: H | X10: ='Formeln Rdx'!AN10 -> 0 | Y10: =IF($K10="L","OK",IF(K10="K","OK",IF(K10="LL","OK","NOK"))) -> OK | Z10: =IF(OR(N10=4,N10="-"),"OK","NOK") -> NOK
A11: 5 | B11: 378078431368 | G11: 4 | H11: 16.4 | K11: K | M11: 60 | N11: =L11+M11 -> 60 | O11: 23.9 | P11: 30 | Q11: 1863 | R11: 3 | S11: 0 | T11: =IF(ISBLANK($B11),"",$U$2) -> Schkeuditz Luftfracht | U11: 100 | V11: D | W11: H | X11: ='Formeln Rdx'!AN11 -> 0 | Y11: =IF($K11="L","OK",IF(K11="K","OK",IF(K11="LL","OK","NOK"))) -> OK | Z11: =IF(OR(N11=4,N11="-"),"OK","NOK") -> NOK
A12: 6 | B12: 378478296023 | G12: 4 | H12: 16.69 | K12: K | L12: 59 | N12: =L12+M12 -> 59 | O12: 22.1 | P12: 30 | Q12: 1863 | R12: 3 | S12: 0 | T12: =IF(ISBLANK($B12),"",$U$2) -> Schkeuditz Luftfracht | U12: 100 | V12: D | W12: H | X12: ='Formeln Rdx'!AN12 -> 0 | Y12: =IF($K12="L","OK",IF(K12="K","OK",IF(K12="LL","OK","NOK"))) -> OK | Z12: =IF(OR(N12=4,N12="-"),"OK","NOK") -> NOK
A13: 7 | B13: 378078431046 | G13: 4 | H13: 16.4 | K13: K | L13: 60 | N13: =L13+M13 -> 60 | O13: 23.9 | P13: 30 | Q13: 1863 | R13: 3 | S13: 0 | T13: =IF(ISBLANK($B13),"",$U$2) -> Schkeuditz Luftfracht | U13: 100 | V13: D | W13: H | X13: ='Formeln Rdx'!AN13 -> 0 | Y13: =IF($K13="L","OK",IF(K13="K","OK",IF(K13="LL","OK","NOK"))) -> OK | Z13: =IF(OR(N13=4,N13="-"),"OK","NOK") -> NOK
A14: 8 | B14: 378078308749 | G14: 4 | H14: 16.4 | K14: K | L14: 58 | N14: =L14+M14 -> 58 | O14: 20.2 | P14: 30 | Q14: 1863 | R14: 3 | S14: 0 | T14: =IF(ISBLANK($B14),"",$U$2) -> Schkeuditz Luftfracht | U14: 100 | V14: D | W14: H | X14: ='Formeln Rdx'!AN14 -> 0 | Y14: =IF($K14="L","OK",IF(K14="K","OK",IF(K14="LL","OK","NOK"))) -> OK | Z14: =IF(OR(N14=4,N14="-"),"OK","NOK") -> NOK
A15: 9 | B15: 378078308970 | G15: 4 | H15: 16.4 | K15: K | L15: 58 | N15: =L15+M15 -> 58 | O15: 20.2 | P15: 30 | Q15: 1863 | R15: 3 | S15: 0 | T15: =IF(ISBLANK($B15),"",$U$2) -> Schkeuditz Luftfracht | U15: 100 | V15: D | W15: H | X15: ='Formeln Rdx'!AN15 -> 0 | Y15: =IF($K15="L","OK",IF(K15="K","OK",IF(K15="LL","OK","NOK"))) -> OK | Z15: =IF(OR(N15=4,N15="-"),"OK","NOK") -> NOK
A16: 10 | B16: 378079291522 | G16: 4 | H16: 16.4 | K16: K | L16: 58 | N16: =L16+M16 -> 58 | O16: 20 | P16: 30 | Q16: 1863 | R16: 3 | S16: 0 | T16: =IF(ISBLANK($B16),"",$U$2) -> Schkeuditz Luftfracht | U16: 100 | V16: D | W16: H | X16: ='Formeln Rdx'!AN16 -> 0 | Y16: =IF($K16="L","OK",IF(K16="K","OK",IF(K16="LL","OK","NOK"))) -> OK | Z16: =IF(OR(N16=4,N16="-"),"OK","NOK") -> NOK
A17: 11 | B17: 378078431459 | G17: 4 | H17: 16.4 | K17: K | L17: 60 | N17: =L17+M17 -> 60 | O17: 23.9 | P17: 30 | Q17: 1863 | R17: 3 | S17: 0 | T17: =IF(ISBLANK($B17),"",$U$2) -> Schkeuditz Luftfracht | U17: 100 | V17: D | W17: H | X17: ='Formeln Rdx'!AN17 -> 0 | Y17: =IF($K17="L","OK",IF(K17="K","OK",IF(K17="LL","OK","NOK"))) -> OK | Z17: =IF(OR(N17=4,N17="-"),"OK","NOK") -> NOK
A18: 12 | B18: 378478296239 | G18: 4 | H18: 16.69 | K18: K | L18: 59 | N18: =L18+M18 -> 59 | O18: 22.1 | P18: 30 | Q18: 1863 | R18: 3 | S18: 0 | T18: =IF(ISBLANK($B18),"",$U$2) -> Schkeuditz Luftfracht | U18: 100 | V18: D | W18: H | X18: ='Formeln Rdx'!AN18 -> 0 | Y18: =IF($K18="L","OK",IF(K18="K","OK",IF(K18="LL","OK","NOK"))) -> OK | Z18: =IF(OR(N18=4,N18="-"),"OK","NOK") -> NOK
A19: 13 | B19: 378078308723 | G19: 4 | H19: 16.4 | K19: K | L19: 58 | N19: =L19+M19 -> 58 | O19: 20.2 | P19: 30 | Q19: 1863 | R19: 3 | S19: 0 | T19: =IF(ISBLANK($B19),"",$U$2) -> Schkeuditz Luftfracht | U19: 100 | V19: D | W19: H | X19: ='Formeln Rdx'!AN19 -> 0 | Y19: =IF($K19="L","OK",IF(K19="K","OK",IF(K19="LL","OK","NOK"))) -> OK | Z19: =IF(OR(N19=4,N19="-"),"OK","NOK") -> NOK
A20: 14 | B20: 338078369851 | G20: 4 | H20: 16.69 | K20: K | L20: 60 | N20: =L20+M20 -> 60 | O20: 22.1 | P20: 30 | Q20: 1863 | R20: 3 | S20: 0 | T20: =IF(ISBLANK($B20),"",$U$2) -> Schkeuditz Luftfracht | U20: 100 | V20: D | W20: H | X20: ='Formeln Rdx'!AN20 -> 0 | Y20: =IF($K20="L","OK",IF(K20="K","OK",IF(K20="LL","OK","NOK"))) -> OK | Z20: =IF(OR(N20=4,N20="-"),"OK","NOK") -> NOK
A21: 15 | B21: 338078369836 | G21: 4 | H21: 16.6 | K21: K | L21: 60 | N21: =L21+M21 -> 60 | O21: 23.1 | P21: 30 | Q21: 1863 | R21: 3 | S21: 0 | T21: =IF(ISBLANK($B21),"",$U$2) -> Schkeuditz Luftfracht | U21: 100 | V21: D | W21: H | X21: ='Formeln Rdx'!AN21 -> 0 | Y21: =IF($K21="L","OK",IF(K21="K","OK",IF(K21="LL","OK","NOK"))) -> OK | Z21: =IF(OR(N21=4,N21="-"),"OK","NOK") -> NOK
A22: 16 | B22: 378478296288 | G22: 4 | H22: 16.69 | K22: K | L22: 59 | N22: =L22+M22 -> 59 | O22: 22.1 | P22: 30 | Q22: 1863 | R22: 3 | S22: 0 | T22: =IF(ISBLANK($B22),"",$U$2) -> Schkeuditz Luftfracht | U22: 100 | V22: D | W22: H | X22: ='Formeln Rdx'!AN22 -> 0 | Y22: =IF($K22="L","OK",IF(K22="K","OK",IF(K22="LL","OK","NOK"))) -> OK | Z22: =IF(OR(N22=4,N22="-"),"OK","NOK") -> NOK
A23: 17 | B23: 335478460553 | G23: 4 | H23: 16.4 | K23: K | L23: 58 | N23: =L23+M23 -> 58 | O23: 20.2 | P23: 30 | Q23: 1863 | R23: 3 | S23: 0 | T23: =IF(ISBLANK($B23),"",$U$2) -> Schkeuditz Luftfracht | U23: 100 | V23: D | W23: H | X23: ='Formeln Rdx'!AN23 -> 0 | Y23: =IF($K23="L","OK",IF(K23="K","OK",IF(K23="LL","OK","NOK"))) -> OK | Z23: =IF(OR(N23=4,N23="-"),"OK","NOK") -> NOK
... A26: 20 | B26: 378079297701 | G26: 4 | H26: 16.4 | K26: K | L26: 59 | N26: =L26+M26 -> 59 | O26: 23.8 | P26: 30 | Q26: 1863 | R26: 3 | S26: 0 | T26: =IF(ISBLANK($B26),"",$U$2) -> Schkeuditz Luftfracht | U26: 100 | V26: D | W26: H | X26: ='Formeln Rdx'!AN26 -> 0 | Y26: =IF($K26="L","OK",IF(K26="K","OK",IF(K26="LL","OK","NOK"))) -> OK | Z26: =IF(OR(N26=4,N26="-"),"OK","NOK") -> NOK
A27: 21 | N27: =L27+M27 -> 0 | T27: =IF(ISBLANK($B27),"",$U$2) | U27: 100 | V27: D | W27: H | X27: ='Formeln Rdx'!AN27 -> 0 | Y27: =IF($K27="L","OK",IF(K27="K","OK",IF(K27="LL","OK","NOK"))) -> NOK | Z27: =IF(OR(N27=4,N27="-"),"OK","NOK") -> NOK
A28: 22 | N28: =L28+M28 -> 0 | T28: =IF(ISBLANK($B28),"",$U$2) | U28: 100 | V28: D | W28: H | X28: ='Formeln Rdx'!AN28 -> 0 | Y28: =IF($K28="L","OK",IF(K28="K","OK",IF(K28="LL","OK","NOK"))) -> NOK | Z28: =IF(OR(N28=4,N28="-"),"OK","NOK") -> NOK
A29: 23 | N29: =L29+M29 -> 0 | T29: =IF(ISBLANK($B29),"",$U$2) | U29: 100 | V29: D | W29: H | X29: ='Formeln Rdx'!AN29 -> 0 | Y29: =IF($K29="L","OK",IF(K29="K","OK",IF(K29="LL","OK","NOK"))) -> NOK | Z29: =IF(OR(N29=4,N29="-"),"OK","NOK") -> NOK
A30: 24 | N30: =L30+M30 -> 0 | T30: =IF(ISBLANK($B30),"",$U$2) | U30: 100 | V30: D | W30: H | X30: ='Formeln Rdx'!AN30 -> 0 | Y30: =IF($K30="L","OK",IF(K30="K","OK",IF(K30="LL","OK","NOK"))) -> NOK | Z30: =IF(OR(N30=4,N30="-"),"OK","NOK") -> NOK
A31: 25 | N31: =L31+M31 -> 0 | T31: =IF(ISBLANK($B31),"",$U$2) | U31: 100 | V31: D | W31: H | X31: ='Formeln Rdx'!AN31 -> 0 | Y31: =IF($K31="L","OK",IF(K31="K","OK",IF(K31="LL","OK","NOK"))) -> NOK | Z31: =IF(OR(N31=4,N31="-"),"OK","NOK") -> NOK
A32: 26 | N32: =L32+M32 -> 0 | T32: =IF(ISBLANK($B32),"",$U$2) | U32: 100 | V32: D | W32: H | X32: ='Formeln Rdx'!AN32 -> 0 | Y32: =IF($K32="L","OK",IF(K32="K","OK",IF(K32="LL","OK","NOK"))) -> NOK | Z32: =IF(OR(N32=4,N32="-"),"OK","NOK") -> NOK
A33: 27 | N33: =L33+M33 -> 0 | T33: =IF(ISBLANK($B33),"",$U$2) | U33: 100 | V33: D | W33: H | X33: ='Formeln Rdx'!AN33 -> 0 | Y33: =IF($K33="L","OK",IF(K33="K","OK",IF(K33="LL","OK","NOK"))) -> NOK | Z33: =IF(OR(N33=4,N33="-"),"OK","NOK") -> NOK
A34: 28 | N34: =L34+M34 -> 0 | T34: =IF(ISBLANK($B34),"",$U$2) | U34: 100 | V34: D | W34: H | X34: ='Formeln Rdx'!AN34 -> 0 | Y34: =IF($K34="L","OK",IF(K34="K","OK",IF(K34="LL","OK","NOK"))) -> NOK | Z34: =IF(OR(N34=4,N34="-"),"OK","NOK") -> NOK
A35: 29 | N35: =L35+M35 -> 0 | T35: =IF(ISBLANK($B35),"",$U$2) | U35: 100 | V35: D | W35: H | X35: ='Formeln Rdx'!AN35 -> 0 | Y35: =IF($K35="L","OK",IF(K35="K","OK",IF(K35="LL","OK","NOK"))) -> NOK | Z35: =IF(OR(N35=4,N35="-"),"OK","NOK") -> NOK
A36: 30 | N36: =L36+M36 -> 0 | T36: =IF(ISBLANK($B36),"",$U$2) | U36: 100 | V36: D | W36: H | X36: ='Formeln Rdx'!AN36 -> 0 | Y36: =IF($K36="L","OK",IF(K36="K","OK",IF(K36="LL","OK","NOK"))) -> NOK | Z36: =IF(OR(N36=4,N36="-"),"OK","NOK") -> NOK
A37: ∑ | B37: =COUNT(B7:F36) -> 20 | G37: =SUM(G7:G36) -> 80 | H37: =SUM(H7:H36) -> 330.23 | I37: =SUM(I7:I36) -> 66.3 | J37: =ROUNDUP(SUM(J7:J36),0) -> 90 | K37: =COUNTA(K7:K36) -> 20 | L37: =ROUNDDOWN(SUM(L7:L36),0) -> 884 | M37: =SUM(M7:M36) -> 298 | N37: =SUM(N7:N36) -> 1182 | O37: =SUM(O7:O36) -> 441
M38: -0.25
L39: =IF(L37>0,L37*(100%+L38),L37) -> 884 | M39: =IF(M37>0,M37*(100%+M38),M37) -> 223.5
L40: =L39+M39 -> 1107.5
A41: 61 Erstellungsdatum | G41: 62 Erstellungszeit | J41: 63 erstellt durch Mitarbeiter
A42: 28. 02 2026 | G42: 0.11805556 | J42: N.Uka
A44: Erläuterung der Felder:
...

Sheet Wagenliste2 (autom. gefüllt)
S6: Gelsen-Log, Am Stadthafen 45, 45881 Gelsenkirchen, Tel.: 0209 - 9541849
A8: Wagenliste für Güterzüge
N9: Seite: | O9: 1 | P9: von | Q9: 1
A11: Datum | F11: Zugnummer | J11: von | N11: nach
A12: =Wagenliste!$A$42 -> 28. 02 2026 | F12: =Wagenliste!$M$2 -> 0 | J12: =Wagenliste!$P$2 -> EGBK | N12: =Wagenliste!$U$2 -> Schkeuditz Luftfracht | S12: Ersteller: | T12: =Wagenliste!$J$42 -> N.Uka
A15: Lfn. A - Z | B15: Lfn. Z - A | C15: Wagennummer | H15: Gattungs- buchstaben | I15: Anzahl der Achsen | K15: Länge über Puffer | L15: Eigen-gewicht | M15: Gewicht der Ladung | N15: Gesamt- gewicht | O15: Bremsgewicht | Q15: Ⓚ, Ⓛ oder LL | R15: Handbrems- gewicht | S15: Abgangsbahnhof | T15: Bestimmungsbahnhof | U15: RID | V15: Bemerkung
O16: P | P16: G
C17: 1-2 | D17: 3-4 | E17: 5-8 | F17: 9-11 | G17: 12 | I17: leer | J17: beladen | K17: m | L17: t | M17: t | N17: t
A18: 1 | B18: =B19+1 -> 30 | C18: =IF(ISBLANK(Wagenliste!B7),"",Wagenliste!B7) -> 378078308871 | H18: =IF(C18="","","Z") -> Z | I18: =IF(OR(M18="0",M18=""),Wagenliste!G7,"-") -> - | J18: =IF(M18="0","-",IF(M18>0,Wagenliste!G7,"-")) -> 4 | K18: =IF(ISBLANK(Wagenliste!H7),"",Wagenliste!H7) -> 16.4 | L18: =IF(C18="","",N18-M18) -> 22.9 | M18: =IF(C18="","",IF(OR(ISBLANK(Wagenliste!I7),Wagenliste!I7=0),"0",Wagenliste!I7)) -> 66.3 | N18: =IF(ISBLANK(Wagenliste!J7),"",Wagenliste!J7) -> 89.2 | O18: =IF(C18="","",IF(Wagenliste!L7="","",Wagenliste!L7)) | P18: =IF(C18="","",IF(Wagenliste!M7="","",Wagenliste!M7)) -> 59 | Q18: =IF(C18="","",Wagenliste!K7) -> K | R18: =IF(ISBLANK(Wagenliste!O7),"",Wagenliste!O7) -> 20.2 | S18: =IF(C18="","",Wagenliste!$P$2) -> EGBK | T18: =IF(C18="","",Wagenliste!$U$2) -> Schkeuditz Luftfracht | U18: =IF(C18="","","X") -> X | V18: =IF(C18="","",(CONCATENATE(Wagenliste!$Q$6," ",Wagenliste!Q7," ",Wagenliste!$R$6," ",Wagenliste!R7," ",Wagenliste!W7))) -> UN Nr 1863 Gef. Zettel 3 H
A19: =A18+1 -> 2 | B19: =B20+1 -> 29 | C19: =IF(ISBLANK(Wagenliste!B8),"",Wagenliste!B8) -> 378078430758 | H19: =IF(C19="","","Z") -> Z | I19: =IF(OR(M19="0",M19=""),Wagenliste!G8,"-") -> 4 | J19: =IF(M19="0","-",IF(M19>0,Wagenliste!G8,"-")) -> - | K19: =IF(ISBLANK(Wagenliste!H8),"",Wagenliste!H8) -> 16.4 | L19: =IF(C19="","",N19-M19) -> #VALUE! | M19: =IF(C19="","",IF(OR(ISBLANK(Wagenliste!I8),Wagenliste!I8=0),"0",Wagenliste!I8)) -> 0 | N19: =IF(ISBLANK(Wagenliste!J8),"",Wagenliste!J8) | O19: =IF(C19="","",IF(Wagenliste!L8="","",Wagenliste!L8)) | P19: =IF(C19="","",IF(Wagenliste!M8="","",Wagenliste!M8)) -> 60 | Q19: =IF(C19="","",Wagenliste!K8) -> K | R19: =IF(ISBLANK(Wagenliste!O8),"",Wagenliste!O8) -> 23.9 | S19: =IF(C19="","",Wagenliste!$P$2) -> EGBK | T19: =IF(C19="","",Wagenliste!$U$2) -> Schkeuditz Luftfracht | U19: =IF(C19="","","X") -> X | V19: =IF(C19="","",(CONCATENATE(Wagenliste!$Q$6," ",Wagenliste!Q8," ",Wagenliste!$R$6," ",Wagenliste!R8," ",Wagenliste!W8))) -> UN Nr 1863 Gef. Zettel 3 H
A20: =A19+1 -> 3 | B20: =B21+1 -> 28 | C20: =IF(ISBLANK(Wagenliste!B9),"",Wagenliste!B9) -> 378078430659 | H20: =IF(C20="","","Z") -> Z | I20: =IF(OR(M20="0",M20=""),Wagenliste!G9,"-") -> 4 | J20: =IF(M20="0","-",IF(M20>0,Wagenliste!G9,"-")) -> - | K20: =IF(ISBLANK(Wagenliste!H9),"",Wagenliste!H9) -> 16.4 | L20: =IF(C20="","",N20-M20) -> #VALUE! | M20: =IF(C20="","",IF(OR(ISBLANK(Wagenliste!I9),Wagenliste!I9=0),"0",Wagenliste!I9)) -> 0 | N20: =IF(ISBLANK(Wagenliste!J9),"",Wagenliste!J9) | O20: =IF(C20="","",IF(Wagenliste!L9="","",Wagenliste!L9)) | P20: =IF(C20="","",IF(Wagenliste!M9="","",Wagenliste!M9)) -> 60 | Q20: =IF(C20="","",Wagenliste!K9) -> K | R20: =IF(ISBLANK(Wagenliste!O9),"",Wagenliste!O9) -> 23.8 | S20: =IF(C20="","",Wagenliste!$P$2) -> EGBK | T20: =IF(C20="","",Wagenliste!$U$2) -> Schkeuditz Luftfracht | U20: =IF(C20="","","X") -> X | V20: =IF(C20="","",(CONCATENATE(Wagenliste!$Q$6," ",Wagenliste!Q9," ",Wagenliste!$R$6," ",Wagenliste!R9," ",Wagenliste!W9))) -> UN Nr 1863 Gef. Zettel 3 H
A21: =A20+1 -> 4 | B21: =B22+1 -> 27 | C21: =IF(ISBLANK(Wagenliste!B10),"",Wagenliste!B10) -> 378478296361 | H21: =IF(C21="","","Z") -> Z | I21: =IF(OR(M21="0",M21=""),Wagenliste!G10,"-") -> 4 | J21: =IF(M21="0","-",IF(M21>0,Wagenliste!G10,"-")) -> - | K21: =IF(ISBLANK(Wagenliste!H10),"",Wagenliste!H10) -> 16.69 | L21: =IF(C21="","",N21-M21) -> #VALUE! | M21: =IF(C21="","",IF(OR(ISBLANK(Wagenliste!I10),Wagenliste!I10=0),"0",Wagenliste!I10)) -> 0 | N21: =IF(ISBLANK(Wagenliste!J10),"",Wagenliste!J10) | O21: =IF(C21="","",IF(Wagenliste!L10="","",Wagenliste!L10)) | P21: =IF(C21="","",IF(Wagenliste!M10="","",Wagenliste!M10)) -> 59 | Q21: =IF(C21="","",Wagenliste!K10) -> K | R21: =IF(ISBLANK(Wagenliste!O10),"",Wagenliste!O10) -> 22.1 | S21: =IF(C21="","",Wagenliste!$P$2) -> EGBK | T21: =IF(C21="","",Wagenliste!$U$2) -> Schkeuditz Luftfracht | U21: =IF(C21="","","X") -> X | V21: =IF(C21="","",(CONCATENATE(Wagenliste!$Q$6," ",Wagenliste!Q10," ",Wagenliste!$R$6," ",Wagenliste!R10," ",Wagenliste!W10))) -> UN Nr 1863 Gef. Zettel 3 H
A22: =A21+1 -> 5 | B22: =B23+1 -> 26 | C22: =IF(ISBLANK(Wagenliste!B11),"",Wagenliste!B11) -> 378078431368 | H22: =IF(C22="","","Z") -> Z | I22: =IF(OR(M22="0",M22=""),Wagenliste!G11,"-") -> 4 | J22: =IF(M22="0","-",IF(M22>0,Wagenliste!G11,"-")) -> - | K22: =IF(ISBLANK(Wagenliste!H11),"",Wagenliste!H11) -> 16.4 | L22: =IF(C22="","",N22-M22) -> #VALUE! | M22: =IF(C22="","",IF(OR(ISBLANK(Wagenliste!I11),Wagenliste!I11=0),"0",Wagenliste!I11)) -> 0 | N22: =IF(ISBLANK(Wagenliste!J11),"",Wagenliste!J11) | O22: =IF(C22="","",IF(Wagenliste!L11="","",Wagenliste!L11)) | P22: =IF(C22="","",IF(Wagenliste!M11="","",Wagenliste!M11)) -> 60 | Q22: =IF(C22="","",Wagenliste!K11) -> K | R22: =IF(ISBLANK(Wagenliste!O11),"",Wagenliste!O11) -> 23.9 | S22: =IF(C22="","",Wagenliste!$P$2) -> EGBK | T22: =IF(C22="","",Wagenliste!$U$2) -> Schkeuditz Luftfracht | U22: =IF(C22="","","X") -> X | V22: =IF(C22="","",(CONCATENATE(Wagenliste!$Q$6," ",Wagenliste!Q11," ",Wagenliste!$R$6," ",Wagenliste!R11," ",Wagenliste!W11))) -> UN Nr 1863 Gef. Zettel 3 H
A23: =A22+1 -> 6 | B23: =B24+1 -> 25 | C23: =IF(ISBLANK(Wagenliste!B12),"",Wagenliste!B12) -> 378478296023 | H23: =IF(C23="","","Z") -> Z | I23: =IF(OR(M23="0",M23=""),Wagenliste!G12,"-") -> 4 | J23: =IF(M23="0","-",IF(M23>0,Wagenliste!G12,"-")) -> - | K23: =IF(ISBLANK(Wagenliste!H12),"",Wagenliste!H12) -> 16.69 | L23: =IF(C23="","",N23-M23) -> #VALUE! | M23: =IF(C23="","",IF(OR(ISBLANK(Wagenliste!I12),Wagenliste!I12=0),"0",Wagenliste!I12)) -> 0 | N23: =IF(ISBLANK(Wagenliste!J12),"",Wagenliste!J12) | O23: =IF(C23="","",IF(Wagenliste!L12="","",Wagenliste!L12)) -> 59 | P23: =IF(C23="","",IF(Wagenliste!M12="","",Wagenliste!M12)) | Q23: =IF(C23="","",Wagenliste!K12) -> K | R23: =IF(ISBLANK(Wagenliste!O12),"",Wagenliste!O12) -> 22.1 | S23: =IF(C23="","",Wagenliste!$P$2) -> EGBK | T23: =IF(C23="","",Wagenliste!$U$2) -> Schkeuditz Luftfracht | U23: =IF(C23="","","X") -> X | V23: =IF(C23="","",(CONCATENATE(Wagenliste!$Q$6," ",Wagenliste!Q12," ",Wagenliste!$R$6," ",Wagenliste!R12," ",Wagenliste!W12))) -> UN Nr 1863 Gef. Zettel 3 H
A24: =A23+1 -> 7 | B24: =B25+1 -> 24 | C24: =IF(ISBLANK(Wagenliste!B13),"",Wagenliste!B13) -> 378078431046 | H24: =IF(C24="","","Z") -> Z | I24: =IF(OR(M24="0",M24=""),Wagenliste!G13,"-") -> 4 | J24: =IF(M24="0","-",IF(M24>0,Wagenliste!G13,"-")) -> - | K24: =IF(ISBLANK(Wagenliste!H13),"",Wagenliste!H13) -> 16.4 | L24: =IF(C24="","",N24-M24) -> #VALUE! | M24: =IF(C24="","",IF(OR(ISBLANK(Wagenliste!I13),Wagenliste!I13=0),"0",Wagenliste!I13)) -> 0 | N24: =IF(ISBLANK(Wagenliste!J13),"",Wagenliste!J13) | O24: =IF(C24="","",IF(Wagenliste!L13="","",Wagenliste!L13)) -> 60 | P24: =IF(C24="","",IF(Wagenliste!M13="","",Wagenliste!M13)) | Q24: =IF(C24="","",Wagenliste!K13) -> K | R24: =IF(ISBLANK(Wagenliste!O13),"",Wagenliste!O13) -> 23.9 | S24: =IF(C24="","",Wagenliste!$P$2) -> EGBK | T24: =IF(C24="","",Wagenliste!$U$2) -> Schkeuditz Luftfracht | U24: =IF(C24="","","X") -> X | V24: =IF(C24="","",(CONCATENATE(Wagenliste!$Q$6," ",Wagenliste!Q13," ",Wagenliste!$R$6," ",Wagenliste!R13," ",Wagenliste!W13))) -> UN Nr 1863 Gef. Zettel 3 H
A25: =A24+1 -> 8 | B25: =B26+1 -> 23 | C25: =IF(ISBLANK(Wagenliste!B14),"",Wagenliste!B14) -> 378078308749 | H25: =IF(C25="","","Z") -> Z | I25: =IF(OR(M25="0",M25=""),Wagenliste!G14,"-") -> 4 | J25: =IF(M25="0","-",IF(M25>0,Wagenliste!G14,"-")) -> - | K25: =IF(ISBLANK(Wagenliste!H14),"",Wagenliste!H14) -> 16.4 | L25: =IF(C25="","",N25-M25) -> #VALUE! | M25: =IF(C25="","",IF(OR(ISBLANK(Wagenliste!I14),Wagenliste!I14=0),"0",Wagenliste!I14)) -> 0 | N25: =IF(ISBLANK(Wagenliste!J14),"",Wagenliste!J14) | O25: =IF(C25="","",IF(Wagenliste!L14="","",Wagenliste!L14)) -> 58 | P25: =IF(C25="","",IF(Wagenliste!M14="","",Wagenliste!M14)) | Q25: =IF(C25="","",Wagenliste!K14) -> K | R25: =IF(ISBLANK(Wagenliste!O14),"",Wagenliste!O14) -> 20.2 | S25: =IF(C25="","",Wagenliste!$P$2) -> EGBK | T25: =IF(C25="","",Wagenliste!$U$2) -> Schkeuditz Luftfracht | U25: =IF(C25="","","X") -> X | V25: =IF(C25="","",(CONCATENATE(Wagenliste!$Q$6," ",Wagenliste!Q14," ",Wagenliste!$R$6," ",Wagenliste!R14," ",Wagenliste!W14))) -> UN Nr 1863 Gef. Zettel 3 H
A26: =A25+1 -> 9 | B26: =B27+1 -> 22 | C26: =IF(ISBLANK(Wagenliste!B15),"",Wagenliste!B15) -> 378078308970 | H26: =IF(C26="","","Z") -> Z | I26: =IF(OR(M26="0",M26=""),Wagenliste!G15,"-") -> 4 | J26: =IF(M26="0","-",IF(M26>0,Wagenliste!G15,"-")) -> - | K26: =IF(ISBLANK(Wagenliste!H15),"",Wagenliste!H15) -> 16.4 | L26: =IF(C26="","",N26-M26) -> #VALUE! | M26: =IF(C26="","",IF(OR(ISBLANK(Wagenliste!I15),Wagenliste!I15=0),"0",Wagenliste!I15)) -> 0 | N26: =IF(ISBLANK(Wagenliste!J15),"",Wagenliste!J15) | O26: =IF(C26="","",IF(Wagenliste!L15="","",Wagenliste!L15)) -> 58 | P26: =IF(C26="","",IF(Wagenliste!M15="","",Wagenliste!M15)) | Q26: =IF(C26="","",Wagenliste!K15) -> K | R26: =IF(ISBLANK(Wagenliste!O15),"",Wagenliste!O15) -> 20.2 | S26: =IF(C26="","",Wagenliste!$P$2) -> EGBK | T26: =IF(C26="","",Wagenliste!$U$2) -> Schkeuditz Luftfracht | U26: =IF(C26="","","X") -> X | V26: =IF(C26="","",(CONCATENATE(Wagenliste!$Q$6," ",Wagenliste!Q15," ",Wagenliste!$R$6," ",Wagenliste!R15," ",Wagenliste!W15))) -> UN Nr 1863 Gef. Zettel 3 H
A27: =A26+1 -> 10 | B27: =B28+1 -> 21 | C27: =IF(ISBLANK(Wagenliste!B16),"",Wagenliste!B16) -> 378079291522 | H27: =IF(C27="","","Z") -> Z | I27: =IF(OR(M27="0",M27=""),Wagenliste!G16,"-") -> 4 | J27: =IF(M27="0","-",IF(M27>0,Wagenliste!G16,"-")) -> - | K27: =IF(ISBLANK(Wagenliste!H16),"",Wagenliste!H16) -> 16.4 | L27: =IF(C27="","",N27-M27) -> #VALUE! | M27: =IF(C27="","",IF(OR(ISBLANK(Wagenliste!I16),Wagenliste!I16=0),"0",Wagenliste!I16)) -> 0 | N27: =IF(ISBLANK(Wagenliste!J16),"",Wagenliste!J16) | O27: =IF(C27="","",IF(Wagenliste!L16="","",Wagenliste!L16)) -> 58 | P27: =IF(C27="","",IF(Wagenliste!M16="","",Wagenliste!M16)) | Q27: =IF(C27="","",Wagenliste!K16) -> K | R27: =IF(ISBLANK(Wagenliste!O16),"",Wagenliste!O16) -> 20 | S27: =IF(C27="","",Wagenliste!$P$2) -> EGBK | T27: =IF(C27="","",Wagenliste!$U$2) -> Schkeuditz Luftfracht | U27: =IF(C27="","","X") -> X | V27: =IF(C27="","",(CONCATENATE(Wagenliste!$Q$6," ",Wagenliste!Q16," ",Wagenliste!$R$6," ",Wagenliste!R16," ",Wagenliste!W16))) -> UN Nr 1863 Gef. Zettel 3 H
A28: =A27+1 -> 11 | B28: =B29+1 -> 20 | C28: =IF(ISBLANK(Wagenliste!B17),"",Wagenliste!B17) -> 378078431459 | H28: =IF(C28="","","Z") -> Z | I28: =IF(OR(M28="0",M28=""),Wagenliste!G17,"-") -> 4 | J28: =IF(M28="0","-",IF(M28>0,Wagenliste!G17,"-")) -> - | K28: =IF(ISBLANK(Wagenliste!H17),"",Wagenliste!H17) -> 16.4 | L28: =IF(C28="","",N28-M28) -> #VALUE! | M28: =IF(C28="","",IF(OR(ISBLANK(Wagenliste!I17),Wagenliste!I17=0),"0",Wagenliste!I17)) -> 0 | N28: =IF(ISBLANK(Wagenliste!J17),"",Wagenliste!J17) | O28: =IF(C28="","",IF(Wagenliste!L17="","",Wagenliste!L17)) -> 60 | P28: =IF(C28="","",IF(Wagenliste!M17="","",Wagenliste!M17)) | Q28: =IF(C28="","",Wagenliste!K17) -> K | R28: =IF(ISBLANK(Wagenliste!O17),"",Wagenliste!O17) -> 23.9 | S28: =IF(C28="","",Wagenliste!$P$2) -> EGBK | T28: =IF(C28="","",Wagenliste!$U$2) -> Schkeuditz Luftfracht | U28: =IF(C28="","","X") -> X | V28: =IF(C28="","",(CONCATENATE(Wagenliste!$Q$6," ",Wagenliste!Q17," ",Wagenliste!$R$6," ",Wagenliste!R17," ",Wagenliste!W17))) -> UN Nr 1863 Gef. Zettel 3 H
A29: =A28+1 -> 12 | B29: =B30+1 -> 19 | C29: =IF(ISBLANK(Wagenliste!B18),"",Wagenliste!B18) -> 378478296239 | H29: =IF(C29="","","Z") -> Z | I29: =IF(OR(M29="0",M29=""),Wagenliste!G18,"-") -> 4 | J29: =IF(M29="0","-",IF(M29>0,Wagenliste!G18,"-")) -> - | K29: =IF(ISBLANK(Wagenliste!H18),"",Wagenliste!H18) -> 16.69 | L29: =IF(C29="","",N29-M29) -> #VALUE! | M29: =IF(C29="","",IF(OR(ISBLANK(Wagenliste!I18),Wagenliste!I18=0),"0",Wagenliste!I18)) -> 0 | N29: =IF(ISBLANK(Wagenliste!J18),"",Wagenliste!J18) | O29: =IF(C29="","",IF(Wagenliste!L18="","",Wagenliste!L18)) -> 59 | P29: =IF(C29="","",IF(Wagenliste!M18="","",Wagenliste!M18)) | Q29: =IF(C29="","",Wagenliste!K18) -> K | R29: =IF(ISBLANK(Wagenliste!O18),"",Wagenliste!O18) -> 22.1 | S29: =IF(C29="","",Wagenliste!$P$2) -> EGBK | T29: =IF(C29="","",Wagenliste!$U$2) -> Schkeuditz Luftfracht | U29: =IF(C29="","","X") -> X | V29: =IF(C29="","",(CONCATENATE(Wagenliste!$Q$6," ",Wagenliste!Q18," ",Wagenliste!$R$6," ",Wagenliste!R18," ",Wagenliste!W18))) -> UN Nr 1863 Gef. Zettel 3 H
A30: =A29+1 -> 13 | B30: =B31+1 -> 18 | C30: =IF(ISBLANK(Wagenliste!B19),"",Wagenliste!B19) -> 378078308723 | H30: =IF(C30="","","Z") -> Z | I30: =IF(OR(M30="0",M30=""),Wagenliste!G19,"-") -> 4 | J30: =IF(M30="0","-",IF(M30>0,Wagenliste!G19,"-")) -> - | K30: =IF(ISBLANK(Wagenliste!H19),"",Wagenliste!H19) -> 16.4 | L30: =IF(C30="","",N30-M30) -> #VALUE! | M30: =IF(C30="","",IF(OR(ISBLANK(Wagenliste!I19),Wagenliste!I19=0),"0",Wagenliste!I19)) -> 0 | N30: =IF(ISBLANK(Wagenliste!J19),"",Wagenliste!J19) | O30: =IF(C30="","",IF(Wagenliste!L19="","",Wagenliste!L19)) -> 58 | P30: =IF(C30="","",IF(Wagenliste!M19="","",Wagenliste!M19)) | Q30: =IF(C30="","",Wagenliste!K19) -> K | R30: =IF(ISBLANK(Wagenliste!O19),"",Wagenliste!O19) -> 20.2 | S30: =IF(C30="","",Wagenliste!$P$2) -> EGBK | T30: =IF(C30="","",Wagenliste!$U$2) -> Schkeuditz Luftfracht | U30: =IF(C30="","","X") -> X | V30: =IF(C30="","",(CONCATENATE(Wagenliste!$Q$6," ",Wagenliste!Q19," ",Wagenliste!$R$6," ",Wagenliste!R19," ",Wagenliste!W19))) -> UN Nr 1863 Gef. Zettel 3 H
... A46: =A45+1 -> 29 | B46: =B47+1 -> 2 | C46: =IF(ISBLANK(Wagenliste!B35),"",Wagenliste!B35) | H46: =IF(C46="","","Z") | I46: =IF(OR(M46="0",M46=""),Wagenliste!G35,"-") -> 0 | J46: =IF(M46="0","-",IF(M46>0,Wagenliste!G35,"-")) -> 0 | K46: =IF(ISBLANK(Wagenliste!H35),"",Wagenliste!H35) | L46: =IF(C46="","",N46-M46) | M46: =IF(C46="","",IF(OR(ISBLANK(Wagenliste!I35),Wagenliste!I35=0),"0",Wagenliste!I35)) | N46: =IF(ISBLANK(Wagenliste!J35),"",Wagenliste!J35) | O46: =IF(C46="","",IF(Wagenliste!L35="","",Wagenliste!L35)) | P46: =IF(C46="","",IF(Wagenliste!M35="","",Wagenliste!M35)) | Q46: =IF(C46="","",Wagenliste!K35) | R46: =IF(ISBLANK(Wagenliste!O35),"",Wagenliste!O35) | S46: =IF(C46="","",Wagenliste!$P$2) | T46: =IF(C46="","",Wagenliste!$U$2) | U46: =IF(C46="","","X") | V46: =IF(C46="","",(CONCATENATE(Wagenliste!$Q$6," ",Wagenliste!Q35," ",Wagenliste!$R$6," ",Wagenliste!R35," ",Wagenliste!W35)))
A47: =A46+1 -> 30 | B47: 1 | C47: =IF(ISBLANK(Wagenliste!B36),"",Wagenliste!B36) | H47: =IF(C47="","","Z") | I47: =IF(OR(M47="0",M47=""),Wagenliste!G36,"-") -> 0 | J47: =IF(M47="0","-",IF(M47>0,Wagenliste!G36,"-")) -> 0 | K47: =IF(ISBLANK(Wagenliste!H36),"",Wagenliste!H36) | L47: =IF(C47="","",N47-M47) | M47: =IF(C47="","",IF(OR(ISBLANK(Wagenliste!I36),Wagenliste!I36=0),"0",Wagenliste!I36)) | N47: =IF(ISBLANK(Wagenliste!J36),"",Wagenliste!J36) | O47: =IF(C47="","",IF(Wagenliste!L36="","",Wagenliste!L36)) | P47: =IF(C47="","",IF(Wagenliste!M36="","",Wagenliste!M36)) | Q47: =IF(C47="","",Wagenliste!K36) | R47: =IF(ISBLANK(Wagenliste!O36),"",Wagenliste!O36) | S47: =IF(C47="","",Wagenliste!$P$2) | T47: =IF(C47="","",Wagenliste!$U$2) | U47: =IF(C47="","","X") | V47: =IF(C47="","",(CONCATENATE(Wagenliste!$Q$6," ",Wagenliste!Q36," ",Wagenliste!$R$6," ",Wagenliste!R36," ",Wagenliste!W36)))
I48: =SUM(I18:I47) -> 76 | J48: =SUM(J18:J47) -> 4 | K48: =SUM(K18:K47) -> 330.23 | L48: =ROUNDUP(SUM(L18:L47),0) -> #VALUE! | M48: =ROUNDUP(SUM(M18:M47),0) -> 67 | N48: =ROUNDUP(SUM(N18:N47),0) -> 90 | O48: =SUM(O18:O47) -> 884 | P48: =SUM(P18:P47) -> 298 | Q48: =COUNTIF(Q18:Q47,"K")+COUNTIF(Q18:Q47,"L")+COUNTIF(Q18:Q47,"LL") -> 20 | V48: wenn vom Bremsgewicht etwas abgezogen werden muss, immer ein Minuszeichen voransetzen!
A49: Anzahl Wagen | E49: =COUNT(C18:G47) -> 20 | H49: Gesamt: | I49: =I48+J48 -> 80 | O49: 0 | P49: -0.25
O50: =ROUNDDOWN(IF(O48<>0,O48*(100%+O49),O48),0) -> 884 | P50: =ROUNDDOWN(IF(P48<>0,P48*(100%+P49),P48),0) -> 223
O51: =O50+P50 -> 1107

Sheet Bremszettel
A1: Brems- | G1: für Zug | I1: =IF(ISBLANK(Wagenliste!M2),"",Wagenliste!M2) | P1: am | R1: =IF(ISBLANK(Wagenliste!A42),"",Wagenliste!A42) -> 28. 02 2026 | V1: ab | W1: =IF(ISBLANK(Wagenliste!P2),"",Wagenliste!P2) -> EGBK
A2: zettel | G2: für Zug | P2: am | V2: ab
G3: für Zug | P3: am | V3: ab
A5: 1 | F5: 2 | H5: 3 | U5: 4 | W5: 5 | Y5: 6
F6: Zeile | H6: Bezeichnung | U6: Wagenzug | W6: arbeitende | Y6: Gesamtzug
W7: Triebfahrzeuge
A8: Angaben | F8: 1 | H8: Gewicht (t) | U8: =Wagenliste!J37 -> 90
A9: für Reise- | F9: 2 | H9: Bremsgewicht (t) | U9: =Wagenliste!L40 -> 1107.5
A10: und | F10: 3 | H10: Zahl der Achsen | U10: =Wagenliste!$G$37 -> 80
A11: Güterzüge | F11: 4 | H11: Mindestbremshundertstel
F12: 5 | H12: Vorhandene | N12: Zeile 2, Sp 6 x 100
H13: Bremshundertstel | N13: Zeile 1, Sp 6
F14: 6 | H14: Fehlende Bremshundertstel
F15: 7 | H15: Nummer des letzten Fahrzeugs | U15: ='WU Protokoll'!I29 -> 378079297701
F16: 8 | H16: Zahl der einlösigen Bremsen | U16: 0
F17: 9 | H17: Zahl der mehrlösigen Bremsen | U17: =Wagenliste!B37 -> 20
F18: 10 | H18: Zahl der Bremsen mit D | U18: 0
F19: 11 | H19: Zahl der Bremsen mit K oder | U19: =Wagenliste!K37 -> 20
F20: 12 | H20: Zahl der Matrossow-Bremsen | U20: 0
F21: 13 | H21: Länge (m) | U21: =Wagenliste!H37 -> 330.23
F22: 14 | H22: Zahl der gebremsten Achsen
F23: 15 | H23: Zahl de erforderlichen | O23: Zeile 3, Sp 4 x 9
H24: gebremsten Achsen | O24: 10
F25: 16 | H25: Im Wagenzug sind Fahrzeuge, deren | X25: Nicht Zutreffendes schräg durchstreichen
H26: zulässige Geschwindigkeit niedriger ist als | U26: nein / ja *)
H27: die des Zuges
H29: Wenn ja, niedrigste zulässige Geschwin-
H30: digkeit eines Fahrzeuges im Wagenzug | U30: km/h
A31: Besondere | F31: 21 | H31: NBÜ/ep-Bremse an allen Fahrzeugen | U31: nein / ja
A32: Angaben | H32: im Wagenzug vorhanden
A33: für | F33: 22 | H33: Notbremsüberbrückung wirksam | U33: nein / ja
F34: 23 | H34: Im Wagenzug sind Fahrzeuge mit | N34: den Kennbuchstaben h, z oder | U34: nein / ja
F35: 24 | N35: den Kennbuchstaben n oder y | U35: nein / ja
F36: 25 | H36: Im Wagenzug sind ausschließlich | N36: Fahrzeuge mit TB0 | U36: nein / ja
F37: 26 | N37: Fahrzeuge mit "o. ZUB" | U37: nein / ja
F38: 27 | N38: Fahrzeuge mit Kennbuchstaben a | U38: nein / ja
A39: Besondere | F39: 31 | H39: Im Wagenzug sind Fahrzeuge mit | U39: nein / ja
A40: Angaben | H40: gefährlichen Gütern
A41: für | F41: 32 | H41: ep-Bremse an allen Fahrzeugen im | U41: nein / ja
A42: Güterzüge | H42: Wagenzug wirksam
...

Sheet WU Protokoll
K6: Gelsen-Log, Am Stadthafen 45, 45881 Gelsenkirchen, Tel.: 0209 - 9541850
B7: WU / ZP Protokoll
C9: Zugnummer : | G9: =Wagenliste!M2 -> 0 | M9: Datum: | P9: =Wagenliste!A42 -> 28. 02 2026 | W9: Name: | Y9: N.Uka
C11: nach: | G11: =Wagenliste!U2 -> Schkeuditz Luftfracht | M11: Uhrzeit: | P11: =Wagenliste!G42 -> 0.11805556 | W11: Auftragsnummer
C13: Wagenanzahl: | G13: =Wagenliste!B37 -> 20 | M13: Ort:
C15: Achsen: | G15: =Wagenliste!G37 -> 80 | M15: Gleis:
C18: Schlußscheiben gesteckt: | L18: X | M18: ja | Q18: nein
C20: volle Bremsprobe durchgeführt : | L20: X | M20: ja | Q20: nein | X20: Uhrzeit : | AA20: =Wagenliste!G42 -> 0.11805556
C22: Grund: | F22: Ausgang
C24: Gefahrgut: | G24: X | H24: ja | L24: nein
C27: Erstes Fahrzeug | I27: =Wagenliste!B7 -> 378078308871
C29: Letztes Fahrzeug | I29: ='Formeln Rdx'!B42 -> 378079297701
C31: Besonderheiten : | I31: UN. Gef.
C37: Schadwagen
AD38: Werkstattzuführung
C39: Wagennummer | I39: Halter | O39: Schadcode | S39: Beschreibung des Schadens | AD39: sofort | AG39: n.El. | AJ39: n.Bt.
C49: n.El. : nach Entladung | L49: n.Bt. : nach Betriebstechnologie / Schaden muss demnächst behoben werden
B51: Name des Erstellers und Unterschrift | M51: Geschäftsstelle des Erstellers | W51: Ort und Datum
B52: N.Uka | M52: Gelsen - Log | W52: Gelsenkirchen, | AF52: =Wagenliste!A42 -> 28. 02 2026
M53: Am Stadthafen 45
M54: Telefon: +49 (0) 209 / 9541850
M55: 45881 Gelsenkirchen

Sheet Meldezettel
A1: Meldezettel Abstellung | Q1: Meldezettel Zugvorbereitung für Zug
Q2: =IF(ISBLANK(Wagenliste!M2),"",Wagenliste!M2) | S2: am | T2: =TODAY() -> 46249
A3: Abgestellt in | E3: EGBK | Q3: Zugnummer | T3: Datum des Verkehrstages
E4: Betriebsstelle | M4: Gleis | Q4: =E3 -> EGBK
A5: Abgestellt am | Q5: Betriebsstelle | T5: Gleis
E6: Datum | M6: Uhrzeit | Q6: Angaben zum Zug
Q7: Beförderungs-/Begleitpapiere vollzählig | T7: Beförderungsanordnung(en) vollzählig
A8: Gewicht/Achsen | E8: =Wagenliste!J37 -> 90 | H8: =Wagenliste!G37 -> 80 | K8: Erstellt | Q8: Zug verkehrt ohne Beförderungs- | T8: Zug verkehrt mit Dauer-
E9: Tonnen | H9: Achsen | K9: Name (Druckschrift) | Q9: Begleitpapiere | T9: Beförderungsanordnung(en)
A10: Erstes Fahrzeug (vier Endziffern) | K10: Letztes Fahrzeug (vier Endziffern) | Q10: Nummer des ersten Fahrzeuges des Wagenzuges | T10: Nummer des letzten Fahrzeuges des Wagenzuges
A11: ='Formeln Rdx'!D47 -> 8 | C11: ='Formeln Rdx'!E47 -> 8 | E11: ='Formeln Rdx'!F47 -> 7 | G11: ___ | I11: ='Formeln Rdx'!C7 -> 1 | K11: ='Formeln Rdx'!D42 -> 7 | L11: ='Formeln Rdx'!E42 -> 7 | M11: ='Formeln Rdx'!F42 -> 0 | N11: ___ | O11: ='Formeln Rdx'!G42 -> 1 | Q11: ='Formeln Rdx'!B47 -> 378078308871 | T11: ='Formeln Rdx'!B42 -> 378079297701
A13: Angaben zur Sicherung (zutreffendes ankreuzen) | Q13: Angaben zum Zug bestätigt | S13: =IF(ISBLANK(Wagenliste!J42),"",Wagenliste!J42) -> N.Uka
A14: Sicherung nur mit Druckluftbremse | S14: Name (Druckschrift)
A16: Sicherung nur mit Triebfahrzeug | Q16: Durchgeführte Tätigkeiten der Zugvorbereitung
A17: Hemmschuhe Radvorleger | E17: Feststell- bremsen | H17: Lastwechsel | K17: Fahrzeugnummer (vier Endziffern) | Q17: Tätigkeit | S17: Auftrag | T17: Datum Uhrzeit Name (Druckschrift)
N18: ___ | Q18: 1. ordnungsgemäßer Kuppelzustand geprüft | T18: 25.02.2026 - 20:43 - N.Uka
N19: ___ | Q19: 2. wagentechnische Behandlung Stufe 3 durchgeführt | T19: 25.02.2026 - 20:43 - N.Uka
N20: ___ | Q20: 3. volle Bremsprobe durchgeführt | T20: 25.02.2026 - 20:43 - N.Uka
N21: ___ | Q21: 4. Schlusssignal angebracht | T21: 25.02.2026 - 20:43 - N.Uka
N22: ___ | Q22: 5. Nummer der Beförderungs-anordnung(en) dem Fahrdienstleiter mitgeteilt | T22: - N.Uka
N23: ___ | T23: ___.___.____ - ___:___ - ______________
N24: ___ | Q24: 6. Triebfahrzeug(e) gekuppelt | T24: ___.___.____ - ___:___ - ______________
N25: ___ | Q25: 7. Sicherung gegen unbeabsichtigtes Bewegen aufgehoben | T25: ___.___.____ - ___:___ - ______________
N26: ___ | Q26: 8. vereinfachte Bremsprobe durchgeführt | T26: ___.___.____ - ___:___ - ______________
N27: ___ | Q27: Noch auszuführende Zusatzarbeiten für den Abschluss der Zugvorbereitung Lfd.-Nr. Auftrag Erledigt (Name)
N28: ___ | Q28: 6
N29: ___ | Q29: 7
Q30: 8

Sheet Formeln Rdx
B1: Zerlegung Wagennummern | O1: Multiplikation Algorythmus | Z1: Quersumme Algorythmus
A2: Lfd-Nr. | B2: Wagennummer | C2: Prüfziffer | D2: 1. St. | E2: 2. St. | F2: 3. St. | G2: 4. St. | H2: 5. St. | I2: 6. St. | J2: 7.St. | K2: 8. St. | L2: 9. St. | M2: 10. St. | N2: 11. St. | O2: M. 1. St. | P2: M. 2.St. | Q2: M. 3.St. | R2: M. 4.St. | S2: M. 5.St. | T2: M. 6.St. | U2: M. 7.St. | V2: M. 8.St. | W2: M. 9.St. | X2: M. 10.St. | Y2: M. 11.St. | Z2: Q. 1.St. | AA2: Q. 2.St. | AB2: Q. 3.St. | AC2: Q. 4.St. | AD2: Q. 5.St. | AE2: Q. 6.St. | AF2: Q. 7.St. | AG2: Q. 8.St. | AH2: Q. 9.St. | AI2: Q. 10.St. | AJ2: Q. 11.St. | AK2: Quersumme ges. | AL2: Nächsthöhere Zehnerzahl | AM2: Errechnete Kontrollziffer | AO2: Prüfung Wagennummer zu lang?
A7: 1 | B7: =Wagenliste!B7 -> 378078308871 | C7: =IF(ISBLANK(Wagenliste!B7),"",ROUND(MID(B7,12,1),0)) -> 1 | D7: =MID(B7,1,1) -> 3 | E7: =MID(B7,2,1) -> 7 | F7: =MID(B7,3,1) -> 8 | G7: =MID(B7,4,1) -> 0 | H7: =MID(B7,5,1) -> 7 | I7: =MID(B7,6,1) -> 8 | J7: =MID(B7,7,1) -> 3 | K7: =MID(B7,8,1) -> 0 | L7: =MID(B7,9,1) -> 8 | M7: =MID(B7,10,1) -> 8 | N7: =MID(B7,11,1) -> 7 | O7: =D7*2 -> 6 | P7: =E7*1 -> 7 | Q7: =F7*2 -> 16 | R7: =G7*1 -> 0 | S7: =H7*2 -> 14 | T7: =I7*1 -> 8 | U7: =J7*2 -> 6 | V7: =K7*1 -> 0 | W7: =L7*2 -> 16 | X7: =M7*1 -> 8 | Y7: =N7*2 -> 14 | Z7: =IF(O7>=10,MID(O7,1,1)+MID(O7,2,1),O7) -> 6 | AA7: =IF(P7>=10,MID(P7,1,1)+MID(P7,2,1),P7) -> 7 | AB7: =IF(Q7>=10,MID(Q7,1,1)+MID(Q7,2,1),Q7) -> 7 | AC7: =IF(R7>=10,MID(R7,1,1)+MID(R7,2,1),R7) -> 0 | AD7: =IF(S7>=10,MID(S7,1,1)+MID(S7,2,1),S7) -> 5 | AE7: =IF(T7>=10,MID(T7,1,1)+MID(T7,2,1),T7) -> 8 | AF7: =IF(U7>=10,MID(U7,1,1)+MID(U7,2,1),U7) -> 6 | AG7: =IF(V7>=10,MID(V7,1,1)+MID(V7,2,1),V7) -> 0 | ... AJ7: =IF(Y7>=10,MID(Y7,1,1)+MID(Y7,2,1),Y7) -> 5 | AK7: =SUM(Z7:AJ7) -> 59 | AL7: =ROUNDUP(AK7,-1) -> 60 | AM7: =ROUND(AL7-AK7,0) -> 1 | AN7: =IF(ISBLANK(Wagenliste!B7),0,AM7-C7) -> 0 | AO7: =IF(ISBLANK(Wagenliste!B7),"",IF(LEN(Wagenliste!B7)>12,0,1)) -> 1
A8: 2 | B8: =Wagenliste!B8 -> 378078430758 | C8: =IF(ISBLANK(Wagenliste!B8),"",ROUND(MID(B8,12,1),0)) -> 8 | D8: =MID(B8,1,1) -> 3 | E8: =MID(B8,2,1) -> 7 | F8: =MID(B8,3,1) -> 8 | G8: =MID(B8,4,1) -> 0 | H8: =MID(B8,5,1) -> 7 | I8: =MID(B8,6,1) -> 8 | J8: =MID(B8,7,1) -> 4 | K8: =MID(B8,8,1) -> 3 | L8: =MID(B8,9,1) -> 0 | M8: =MID(B8,10,1) -> 7 | N8: =MID(B8,11,1) -> 5 | O8: =D8*2 -> 6 | P8: =E8*1 -> 7 | Q8: =F8*2 -> 16 | R8: =G8*1 -> 0 | S8: =H8*2 -> 14 | T8: =I8*1 -> 8 | U8: =J8*2 -> 8 | V8: =K8*1 -> 3 | W8: =L8*2 -> 0 | X8: =M8*1 -> 7 | Y8: =N8*2 -> 10 | Z8: =IF(O8>=10,MID(O8,1,1)+MID(O8,2,1),O8) -> 6 | AA8: =IF(P8>=10,MID(P8,1,1)+MID(P8,2,1),P8) -> 7 | AB8: =IF(Q8>=10,MID(Q8,1,1)+MID(Q8,2,1),Q8) -> 7 | AC8: =IF(R8>=10,MID(R8,1,1)+MID(R8,2,1),R8) -> 0 | AD8: =IF(S8>=10,MID(S8,1,1)+MID(S8,2,1),S8) -> 5 | AE8: =IF(T8>=10,MID(T8,1,1)+MID(T8,2,1),T8) -> 8 | AF8: =IF(U8>=10,MID(U8,1,1)+MID(U8,2,1),U8) -> 8 | AG8: =IF(V8>=10,MID(V8,1,1)+MID(V8,2,1),V8) -> 3 | ... AJ8: =IF(Y8>=10,MID(Y8,1,1)+MID(Y8,2,1),Y8) -> 1 | AK8: =SUM(Z8:AJ8) -> 52 | AL8: =ROUNDUP(AK8,-1) -> 60 | AM8: =AL8-AK8 -> 8 | AN8: =IF(ISBLANK(Wagenliste!B8),0,AM8-C8) -> 0 | AO8: =IF(ISBLANK(Wagenliste!B8),"",IF(LEN(Wagenliste!B8)>12,0,1)) -> 1
A9: 3 | B9: =Wagenliste!B9 -> 378078430659 | C9: =IF(ISBLANK(Wagenliste!B9),"",ROUND(MID(B9,12,1),0)) -> 9 | D9: =MID(B9,1,1) -> 3 | E9: =MID(B9,2,1) -> 7 | F9: =MID(B9,3,1) -> 8 | G9: =MID(B9,4,1) -> 0 | H9: =MID(B9,5,1) -> 7 | I9: =MID(B9,6,1) -> 8 | J9: =MID(B9,7,1) -> 4 | K9: =MID(B9,8,1) -> 3 | L9: =MID(B9,9,1) -> 0 | M9: =MID(B9,10,1) -> 6 | N9: =MID(B9,11,1) -> 5 | O9: =D9*2 -> 6 | P9: =E9*1 -> 7 | Q9: =F9*2 -> 16 | R9: =G9*1 -> 0 | S9: =H9*2 -> 14 | T9: =I9*1 -> 8 | U9: =J9*2 -> 8 | V9: =K9*1 -> 3 | W9: =L9*2 -> 0 | X9: =M9*1 -> 6 | Y9: =N9*2 -> 10 | Z9: =IF(O9>=10,MID(O9,1,1)+MID(O9,2,1),O9) -> 6 | AA9: =IF(P9>=10,MID(P9,1,1)+MID(P9,2,1),P9) -> 7 | AB9: =IF(Q9>=10,MID(Q9,1,1)+MID(Q9,2,1),Q9) -> 7 | AC9: =IF(R9>=10,MID(R9,1,1)+MID(R9,2,1),R9) -> 0 | AD9: =IF(S9>=10,MID(S9,1,1)+MID(S9,2,1),S9) -> 5 | AE9: =IF(T9>=10,MID(T9,1,1)+MID(T9,2,1),T9) -> 8 | AF9: =IF(U9>=10,MID(U9,1,1)+MID(U9,2,1),U9) -> 8 | AG9: =IF(V9>=10,MID(V9,1,1)+MID(V9,2,1),V9) -> 3 | ... AJ9: =IF(Y9>=10,MID(Y9,1,1)+MID(Y9,2,1),Y9) -> 1 | AK9: =SUM(Z9:AJ9) -> 51 | AL9: =ROUNDUP(AK9,-1) -> 60 | AM9: =AL9-AK9 -> 9 | AN9: =IF(ISBLANK(Wagenliste!B9),0,AM9-C9) -> 0 | AO9: =IF(ISBLANK(Wagenliste!B9),"",IF(LEN(Wagenliste!B9)>12,0,1)) -> 1
A10: 4 | B10: =Wagenliste!B10 -> 378478296361 | C10: =IF(ISBLANK(Wagenliste!B10),"",ROUND(MID(B10,12,1),0)) -> 1 | D10: =MID(B10,1,1) -> 3 | E10: =MID(B10,2,1) -> 7 | F10: =MID(B10,3,1) -> 8 | G10: =MID(B10,4,1) -> 4 | H10: =MID(B10,5,1) -> 7 | I10: =MID(B10,6,1) -> 8 | J10: =MID(B10,7,1) -> 2 | K10: =MID(B10,8,1) -> 9 | L10: =MID(B10,9,1) -> 6 | M10: =MID(B10,10,1) -> 3 | N10: =MID(B10,11,1) -> 6 | O10: =D10*2 -> 6 | P10: =E10*1 -> 7 | Q10: =F10*2 -> 16 | R10: =G10*1 -> 4 | S10: =H10*2 -> 14 | T10: =I10*1 -> 8 | U10: =J10*2 -> 4 | V10: =K10*1 -> 9 | W10: =L10*2 -> 12 | X10: =M10*1 -> 3 | Y10: =N10*2 -> 12 | Z10: =IF(O10>=10,MID(O10,1,1)+MID(O10,2,1),O10) -> 6 | AA10: =IF(P10>=10,MID(P10,1,1)+MID(P10,2,1),P10) -> 7 | AB10: =IF(Q10>=10,MID(Q10,1,1)+MID(Q10,2,1),Q10) -> 7 | AC10: =IF(R10>=10,MID(R10,1,1)+MID(R10,2,1),R10) -> 4 | AD10: =IF(S10>=10,MID(S10,1,1)+MID(S10,2,1),S10) -> 5 | AE10: =IF(T10>=10,MID(T10,1,1)+MID(T10,2,1),T10) -> 8 | AF10: =IF(U10>=10,MID(U10,1,1)+MID(U10,2,1),U10) -> 4 | AG10: =IF(V10>=10,MID(V10,1,1)+MID(V10,2,1),V10) -> 9 | ... AJ10: =IF(Y10>=10,MID(Y10,1,1)+MID(Y10,2,1),Y10) -> 3 | AK10: =SUM(Z10:AJ10) -> 59 | AL10: =ROUNDUP(AK10,-1) -> 60 | AM10: =AL10-AK10 -> 1 | AN10: =IF(ISBLANK(Wagenliste!B10),0,AM10-C10) -> 0 | AO10: =IF(ISBLANK(Wagenliste!B10),"",IF(LEN(Wagenliste!B10)>12,0,1)) -> 1
A11: 5 | B11: =Wagenliste!B11 -> 378078431368 | C11: =IF(ISBLANK(Wagenliste!B11),"",ROUND(MID(B11,12,1),0)) -> 8 | D11: =MID(B11,1,1) -> 3 | E11: =MID(B11,2,1) -> 7 | F11: =MID(B11,3,1) -> 8 | G11: =MID(B11,4,1) -> 0 | H11: =MID(B11,5,1) -> 7 | I11: =MID(B11,6,1) -> 8 | J11: =MID(B11,7,1) -> 4 | K11: =MID(B11,8,1) -> 3 | L11: =MID(B11,9,1) -> 1 | M11: =MID(B11,10,1) -> 3 | N11: =MID(B11,11,1) -> 6 | O11: =D11*2 -> 6 | P11: =E11*1 -> 7 | Q11: =F11*2 -> 16 | R11: =G11*1 -> 0 | S11: =H11*2 -> 14 | T11: =I11*1 -> 8 | U11: =J11*2 -> 8 | V11: =K11*1 -> 3 | W11: =L11*2 -> 2 | X11: =M11*1 -> 3 | Y11: =N11*2 -> 12 | Z11: =IF(O11>=10,MID(O11,1,1)+MID(O11,2,1),O11) -> 6 | AA11: =IF(P11>=10,MID(P11,1,1)+MID(P11,2,1),P11) -> 7 | AB11: =IF(Q11>=10,MID(Q11,1,1)+MID(Q11,2,1),Q11) -> 7 | AC11: =IF(R11>=10,MID(R11,1,1)+MID(R11,2,1),R11) -> 0 | AD11: =IF(S11>=10,MID(S11,1,1)+MID(S11,2,1),S11) -> 5 | AE11: =IF(T11>=10,MID(T11,1,1)+MID(T11,2,1),T11) -> 8 | AF11: =IF(U11>=10,MID(U11,1,1)+MID(U11,2,1),U11) -> 8 | AG11: =IF(V11>=10,MID(V11,1,1)+MID(V11,2,1),V11) -> 3 | ... AJ11: =IF(Y11>=10,MID(Y11,1,1)+MID(Y11,2,1),Y11) -> 3 | AK11: =SUM(Z11:AJ11) -> 52 | AL11: =ROUNDUP(AK11,-1) -> 60 | AM11: =AL11-AK11 -> 8 | AN11: =IF(ISBLANK(Wagenliste!B11),0,AM11-C11) -> 0 | AO11: =IF(ISBLANK(Wagenliste!B11),"",IF(LEN(Wagenliste!B11)>12,0,1)) -> 1
A12: 6 | B12: =Wagenliste!B12 -> 378478296023 | C12: =IF(ISBLANK(Wagenliste!B12),"",ROUND(MID(B12,12,1),0)) -> 3 | D12: =MID(B12,1,1) -> 3 | E12: =MID(B12,2,1) -> 7 | F12: =MID(B12,3,1) -> 8 | G12: =MID(B12,4,1) -> 4 | H12: =MID(B12,5,1) -> 7 | I12: =MID(B12,6,1) -> 8 | J12: =MID(B12,7,1) -> 2 | K12: =MID(B12,8,1) -> 9 | L12: =MID(B12,9,1) -> 6 | M12: =MID(B12,10,1) -> 0 | N12: =MID(B12,11,1) -> 2 | O12: =D12*2 -> 6 | P12: =E12*1 -> 7 | Q12: =F12*2 -> 16 | R12: =G12*1 -> 4 | S12: =H12*2 -> 14 | T12: =I12*1 -> 8 | U12: =J12*2 -> 4 | V12: =K12*1 -> 9 | W12: =L12*2 -> 12 | X12: =M12*1 -> 0 | Y12: =N12*2 -> 4 | Z12: =IF(O12>=10,MID(O12,1,1)+MID(O12,2,1),O12) -> 6 | AA12: =IF(P12>=10,MID(P12,1,1)+MID(P12,2,1),P12) -> 7 | AB12: =IF(Q12>=10,MID(Q12,1,1)+MID(Q12,2,1),Q12) -> 7 | AC12: =IF(R12>=10,MID(R12,1,1)+MID(R12,2,1),R12) -> 4 | AD12: =IF(S12>=10,MID(S12,1,1)+MID(S12,2,1),S12) -> 5 | AE12: =IF(T12>=10,MID(T12,1,1)+MID(T12,2,1),T12) -> 8 | AF12: =IF(U12>=10,MID(U12,1,1)+MID(U12,2,1),U12) -> 4 | AG12: =IF(V12>=10,MID(V12,1,1)+MID(V12,2,1),V12) -> 9 | ... AJ12: =IF(Y12>=10,MID(Y12,1,1)+MID(Y12,2,1),Y12) -> 4 | AK12: =SUM(Z12:AJ12) -> 57 | AL12: =ROUNDUP(AK12,-1) -> 60 | AM12: =AL12-AK12 -> 3 | AN12: =IF(ISBLANK(Wagenliste!B12),0,AM12-C12) -> 0 | AO12: =IF(ISBLANK(Wagenliste!B12),"",IF(LEN(Wagenliste!B12)>12,0,1)) -> 1
A13: 7 | B13: =Wagenliste!B13 -> 378078431046 | C13: =IF(ISBLANK(Wagenliste!B13),"",ROUND(MID(B13,12,1),0)) -> 6 | D13: =MID(B13,1,1) -> 3 | E13: =MID(B13,2,1) -> 7 | F13: =MID(B13,3,1) -> 8 | G13: =MID(B13,4,1) -> 0 | H13: =MID(B13,5,1) -> 7 | I13: =MID(B13,6,1) -> 8 | J13: =MID(B13,7,1) -> 4 | K13: =MID(B13,8,1) -> 3 | L13: =MID(B13,9,1) -> 1 | M13: =MID(B13,10,1) -> 0 | N13: =MID(B13,11,1) -> 4 | O13: =D13*2 -> 6 | P13: =E13*1 -> 7 | Q13: =F13*2 -> 16 | R13: =G13*1 -> 0 | S13: =H13*2 -> 14 | T13: =I13*1 -> 8 | U13: =J13*2 -> 8 | V13: =K13*1 -> 3 | W13: =L13*2 -> 2 | X13: =M13*1 -> 0 | Y13: =N13*2 -> 8 | Z13: =IF(O13>=10,MID(O13,1,1)+MID(O13,2,1),O13) -> 6 | AA13: =IF(P13>=10,MID(P13,1,1)+MID(P13,2,1),P13) -> 7 | AB13: =IF(Q13>=10,MID(Q13,1,1)+MID(Q13,2,1),Q13) -> 7 | AC13: =IF(R13>=10,MID(R13,1,1)+MID(R13,2,1),R13) -> 0 | AD13: =IF(S13>=10,MID(S13,1,1)+MID(S13,2,1),S13) -> 5 | AE13: =IF(T13>=10,MID(T13,1,1)+MID(T13,2,1),T13) -> 8 | AF13: =IF(U13>=10,MID(U13,1,1)+MID(U13,2,1),U13) -> 8 | AG13: =IF(V13>=10,MID(V13,1,1)+MID(V13,2,1),V13) -> 3 | ... AJ13: =IF(Y13>=10,MID(Y13,1,1)+MID(Y13,2,1),Y13) -> 8 | AK13: =SUM(Z13:AJ13) -> 54 | AL13: =ROUNDUP(AK13,-1) -> 60 | AM13: =AL13-AK13 -> 6 | AN13: =IF(ISBLANK(Wagenliste!B13),0,AM13-C13) -> 0 | AO13: =IF(ISBLANK(Wagenliste!B13),"",IF(LEN(Wagenliste!B13)>12,0,1)) -> 1
A14: 8 | B14: =Wagenliste!B14 -> 378078308749 | C14: =IF(ISBLANK(Wagenliste!B14),"",ROUND(MID(B14,12,1),0)) -> 9 | D14: =MID(B14,1,1) -> 3 | E14: =MID(B14,2,1) -> 7 | F14: =MID(B14,3,1) -> 8 | G14: =MID(B14,4,1) -> 0 | H14: =MID(B14,5,1) -> 7 | I14: =MID(B14,6,1) -> 8 | J14: =MID(B14,7,1) -> 3 | K14: =MID(B14,8,1) -> 0 | L14: =MID(B14,9,1) -> 8 | M14: =MID(B14,10,1) -> 7 | N14: =MID(B14,11,1) -> 4 | O14: =D14*2 -> 6 | P14: =E14*1 -> 7 | Q14: =F14*2 -> 16 | R14: =G14*1 -> 0 | S14: =H14*2 -> 14 | T14: =I14*1 -> 8 | U14: =J14*2 -> 6 | V14: =K14*1 -> 0 | W14: =L14*2 -> 16 | X14: =M14*1 -> 7 | Y14: =N14*2 -> 8 | Z14: =IF(O14>=10,MID(O14,1,1)+MID(O14,2,1),O14) -> 6 | AA14: =IF(P14>=10,MID(P14,1,1)+MID(P14,2,1),P14) -> 7 | AB14: =IF(Q14>=10,MID(Q14,1,1)+MID(Q14,2,1),Q14) -> 7 | AC14: =IF(R14>=10,MID(R14,1,1)+MID(R14,2,1),R14) -> 0 | AD14: =IF(S14>=10,MID(S14,1,1)+MID(S14,2,1),S14) -> 5 | AE14: =IF(T14>=10,MID(T14,1,1)+MID(T14,2,1),T14) -> 8 | AF14: =IF(U14>=10,MID(U14,1,1)+MID(U14,2,1),U14) -> 6 | AG14: =IF(V14>=10,MID(V14,1,1)+MID(V14,2,1),V14) -> 0 | ... AJ14: =IF(Y14>=10,MID(Y14,1,1)+MID(Y14,2,1),Y14) -> 8 | AK14: =SUM(Z14:AJ14) -> 61 | AL14: =ROUNDUP(AK14,-1) -> 70 | AM14: =AL14-AK14 -> 9 | AN14: =IF(ISBLANK(Wagenliste!B14),0,AM14-C14) -> 0 | AO14: =IF(ISBLANK(Wagenliste!B14),"",IF(LEN(Wagenliste!B14)>12,0,1)) -> 1
A15: 9 | B15: =Wagenliste!B15 -> 378078308970 | C15: =IF(ISBLANK(Wagenliste!B15),"",ROUND(MID(B15,12,1),0)) -> 0 | D15: =MID(B15,1,1) -> 3 | E15: =MID(B15,2,1) -> 7 | F15: =MID(B15,3,1) -> 8 | G15: =MID(B15,4,1) -> 0 | H15: =MID(B15,5,1) -> 7 | I15: =MID(B15,6,1) -> 8 | J15: =MID(B15,7,1) -> 3 | K15: =MID(B15,8,1) -> 0 | L15: =MID(B15,9,1) -> 8 | M15: =MID(B15,10,1) -> 9 | N15: =MID(B15,11,1) -> 7 | O15: =D15*2 -> 6 | P15: =E15*1 -> 7 | Q15: =F15*2 -> 16 | R15: =G15*1 -> 0 | S15: =H15*2 -> 14 | T15: =I15*1 -> 8 | U15: =J15*2 -> 6 | V15: =K15*1 -> 0 | W15: =L15*2 -> 16 | X15: =M15*1 -> 9 | Y15: =N15*2 -> 14 | Z15: =IF(O15>=10,MID(O15,1,1)+MID(O15,2,1),O15) -> 6 | AA15: =IF(P15>=10,MID(P15,1,1)+MID(P15,2,1),P15) -> 7 | AB15: =IF(Q15>=10,MID(Q15,1,1)+MID(Q15,2,1),Q15) -> 7 | AC15: =IF(R15>=10,MID(R15,1,1)+MID(R15,2,1),R15) -> 0 | AD15: =IF(S15>=10,MID(S15,1,1)+MID(S15,2,1),S15) -> 5 | AE15: =IF(T15>=10,MID(T15,1,1)+MID(T15,2,1),T15) -> 8 | AF15: =IF(U15>=10,MID(U15,1,1)+MID(U15,2,1),U15) -> 6 | AG15: =IF(V15>=10,MID(V15,1,1)+MID(V15,2,1),V15) -> 0 | ... AJ15: =IF(Y15>=10,MID(Y15,1,1)+MID(Y15,2,1),Y15) -> 5 | AK15: =SUM(Z15:AJ15) -> 60 | AL15: =ROUNDUP(AK15,-1) -> 60 | AM15: =AL15-AK15 -> 0 | AN15: =IF(ISBLANK(Wagenliste!B15),0,AM15-C15) -> 0 | AO15: =IF(ISBLANK(Wagenliste!B15),"",IF(LEN(Wagenliste!B15)>12,0,1)) -> 1
A16: 10 | B16: =Wagenliste!B16 -> 378079291522 | C16: =IF(ISBLANK(Wagenliste!B16),"",ROUND(MID(B16,12,1),0)) -> 2 | D16: =MID(B16,1,1) -> 3 | E16: =MID(B16,2,1) -> 7 | F16: =MID(B16,3,1) -> 8 | G16: =MID(B16,4,1) -> 0 | H16: =MID(B16,5,1) -> 7 | I16: =MID(B16,6,1) -> 9 | J16: =MID(B16,7,1) -> 2 | K16: =MID(B16,8,1) -> 9 | L16: =MID(B16,9,1) -> 1 | M16: =MID(B16,10,1) -> 5 | N16: =MID(B16,11,1) -> 2 | O16: =D16*2 -> 6 | P16: =E16*1 -> 7 | Q16: =F16*2 -> 16 | R16: =G16*1 -> 0 | S16: =H16*2 -> 14 | T16: =I16*1 -> 9 | U16: =J16*2 -> 4 | V16: =K16*1 -> 9 | W16: =L16*2 -> 2 | X16: =M16*1 -> 5 | Y16: =N16*2 -> 4 | Z16: =IF(O16>=10,MID(O16,1,1)+MID(O16,2,1),O16) -> 6 | AA16: =IF(P16>=10,MID(P16,1,1)+MID(P16,2,1),P16) -> 7 | AB16: =IF(Q16>=10,MID(Q16,1,1)+MID(Q16,2,1),Q16) -> 7 | AC16: =IF(R16>=10,MID(R16,1,1)+MID(R16,2,1),R16) -> 0 | AD16: =IF(S16>=10,MID(S16,1,1)+MID(S16,2,1),S16) -> 5 | AE16: =IF(T16>=10,MID(T16,1,1)+MID(T16,2,1),T16) -> 9 | AF16: =IF(U16>=10,MID(U16,1,1)+MID(U16,2,1),U16) -> 4 | AG16: =IF(V16>=10,MID(V16,1,1)+MID(V16,2,1),V16) -> 9 | ... AJ16: =IF(Y16>=10,MID(Y16,1,1)+MID(Y16,2,1),Y16) -> 4 | AK16: =SUM(Z16:AJ16) -> 58 | AL16: =ROUNDUP(AK16,-1) -> 60 | AM16: =AL16-AK16 -> 2 | AN16: =IF(ISBLANK(Wagenliste!B16),0,AM16-C16) -> 0 | AO16: =IF(ISBLANK(Wagenliste!B16),"",IF(LEN(Wagenliste!B16)>12,0,1)) -> 1
A17: 11 | B17: =Wagenliste!B17 -> 378078431459 | C17: =IF(ISBLANK(Wagenliste!B17),"",ROUND(MID(B17,12,1),0)) -> 9 | D17: =MID(B17,1,1) -> 3 | E17: =MID(B17,2,1) -> 7 | F17: =MID(B17,3,1) -> 8 | G17: =MID(B17,4,1) -> 0 | H17: =MID(B17,5,1) -> 7 | I17: =MID(B17,6,1) -> 8 | J17: =MID(B17,7,1) -> 4 | K17: =MID(B17,8,1) -> 3 | L17: =MID(B17,9,1) -> 1 | M17: =MID(B17,10,1) -> 4 | N17: =MID(B17,11,1) -> 5 | O17: =D17*2 -> 6 | P17: =E17*1 -> 7 | Q17: =F17*2 -> 16 | R17: =G17*1 -> 0 | S17: =H17*2 -> 14 | T17: =I17*1 -> 8 | U17: =J17*2 -> 8 | V17: =K17*1 -> 3 | W17: =L17*2 -> 2 | X17: =M17*1 -> 4 | Y17: =N17*2 -> 10 | Z17: =IF(O17>=10,MID(O17,1,1)+MID(O17,2,1),O17) -> 6 | AA17: =IF(P17>=10,MID(P17,1,1)+MID(P17,2,1),P17) -> 7 | AB17: =IF(Q17>=10,MID(Q17,1,1)+MID(Q17,2,1),Q17) -> 7 | AC17: =IF(R17>=10,MID(R17,1,1)+MID(R17,2,1),R17) -> 0 | AD17: =IF(S17>=10,MID(S17,1,1)+MID(S17,2,1),S17) -> 5 | AE17: =IF(T17>=10,MID(T17,1,1)+MID(T17,2,1),T17) -> 8 | AF17: =IF(U17>=10,MID(U17,1,1)+MID(U17,2,1),U17) -> 8 | AG17: =IF(V17>=10,MID(V17,1,1)+MID(V17,2,1),V17) -> 3 | ... AJ17: =IF(Y17>=10,MID(Y17,1,1)+MID(Y17,2,1),Y17) -> 1 | AK17: =SUM(Z17:AJ17) -> 51 | AL17: =ROUNDUP(AK17,-1) -> 60 | AM17: =AL17-AK17 -> 9 | AN17: =IF(ISBLANK(Wagenliste!B17),0,AM17-C17) -> 0 | AO17: =IF(ISBLANK(Wagenliste!B17),"",IF(LEN(Wagenliste!B17)>12,0,1)) -> 1
A18: 12 | B18: =Wagenliste!B18 -> 378478296239 | C18: =IF(ISBLANK(Wagenliste!B18),"",ROUND(MID(B18,12,1),0)) -> 9 | D18: =MID(B18,1,1) -> 3 | E18: =MID(B18,2,1) -> 7 | F18: =MID(B18,3,1) -> 8 | G18: =MID(B18,4,1) -> 4 | H18: =MID(B18,5,1) -> 7 | I18: =MID(B18,6,1) -> 8 | J18: =MID(B18,7,1) -> 2 | K18: =MID(B18,8,1) -> 9 | L18: =MID(B18,9,1) -> 6 | M18: =MID(B18,10,1) -> 2 | N18: =MID(B18,11,1) -> 3 | O18: =D18*2 -> 6 | P18: =E18*1 -> 7 | Q18: =F18*2 -> 16 | R18: =G18*1 -> 4 | S18: =H18*2 -> 14 | T18: =I18*1 -> 8 | U18: =J18*2 -> 4 | V18: =K18*1 -> 9 | W18: =L18*2 -> 12 | X18: =M18*1 -> 2 | Y18: =N18*2 -> 6 | Z18: =IF(O18>=10,MID(O18,1,1)+MID(O18,2,1),O18) -> 6 | AA18: =IF(P18>=10,MID(P18,1,1)+MID(P18,2,1),P18) -> 7 | AB18: =IF(Q18>=10,MID(Q18,1,1)+MID(Q18,2,1),Q18) -> 7 | AC18: =IF(R18>=10,MID(R18,1,1)+MID(R18,2,1),R18) -> 4 | AD18: =IF(S18>=10,MID(S18,1,1)+MID(S18,2,1),S18) -> 5 | AE18: =IF(T18>=10,MID(T18,1,1)+MID(T18,2,1),T18) -> 8 | AF18: =IF(U18>=10,MID(U18,1,1)+MID(U18,2,1),U18) -> 4 | AG18: =IF(V18>=10,MID(V18,1,1)+MID(V18,2,1),V18) -> 9 | ... AJ18: =IF(Y18>=10,MID(Y18,1,1)+MID(Y18,2,1),Y18) -> 6 | AK18: =SUM(Z18:AJ18) -> 61 | AL18: =ROUNDUP(AK18,-1) -> 70 | AM18: =AL18-AK18 -> 9 | AN18: =IF(ISBLANK(Wagenliste!B18),0,AM18-C18) -> 0 | AO18: =IF(ISBLANK(Wagenliste!B18),"",IF(LEN(Wagenliste!B18)>12,0,1)) -> 1
A19: 13 | B19: =Wagenliste!B19 -> 378078308723 | C19: =IF(ISBLANK(Wagenliste!B19),"",ROUND(MID(B19,12,1),0)) -> 3 | D19: =MID(B19,1,1) -> 3 | E19: =MID(B19,2,1) -> 7 | F19: =MID(B19,3,1) -> 8 | G19: =MID(B19,4,1) -> 0 | H19: =MID(B19,5,1) -> 7 | I19: =MID(B19,6,1) -> 8 | J19: =MID(B19,7,1) -> 3 | K19: =MID(B19,8,1) -> 0 | L19: =MID(B19,9,1) -> 8 | M19: =MID(B19,10,1) -> 7 | N19: =MID(B19,11,1) -> 2 | O19: =D19*2 -> 6 | P19: =E19*1 -> 7 | Q19: =F19*2 -> 16 | R19: =G19*1 -> 0 | S19: =H19*2 -> 14 | T19: =I19*1 -> 8 | U19: =J19*2 -> 6 | V19: =K19*1 -> 0 | W19: =L19*2 -> 16 | X19: =M19*1 -> 7 | Y19: =N19*2 -> 4 | Z19: =IF(O19>=10,MID(O19,1,1)+MID(O19,2,1),O19) -> 6 | AA19: =IF(P19>=10,MID(P19,1,1)+MID(P19,2,1),P19) -> 7 | AB19: =IF(Q19>=10,MID(Q19,1,1)+MID(Q19,2,1),Q19) -> 7 | AC19: =IF(R19>=10,MID(R19,1,1)+MID(R19,2,1),R19) -> 0 | AD19: =IF(S19>=10,MID(S19,1,1)+MID(S19,2,1),S19) -> 5 | AE19: =IF(T19>=10,MID(T19,1,1)+MID(T19,2,1),T19) -> 8 | AF19: =IF(U19>=10,MID(U19,1,1)+MID(U19,2,1),U19) -> 6 | AG19: =IF(V19>=10,MID(V19,1,1)+MID(V19,2,1),V19) -> 0 | ... AJ19: =IF(Y19>=10,MID(Y19,1,1)+MID(Y19,2,1),Y19) -> 4 | AK19: =SUM(Z19:AJ19) -> 57 | AL19: =ROUNDUP(AK19,-1) -> 60 | AM19: =AL19-AK19 -> 3 | AN19: =IF(ISBLANK(Wagenliste!B19),0,AM19-C19) -> 0 | AO19: =IF(ISBLANK(Wagenliste!B19),"",IF(LEN(Wagenliste!B19)>12,0,1)) -> 1
... A36: 30 | B36: =Wagenliste!B36 -> 0 | C36: =IF(ISBLANK(Wagenliste!B36),"",ROUND(MID(B36,12,1),0)) | D36: =MID(B36,1,1) -> 0 | E36: =MID(B36,2,1) | F36: =MID(B36,3,1) | G36: =MID(B36,4,1) | H36: =MID(B36,5,1) | I36: =MID(B36,6,1) | J36: =MID(B36,7,1) | K36: =MID(B36,8,1) | L36: =MID(B36,9,1) | M36: =MID(B36,10,1) | N36: =MID(B36,11,1) | O36: =D36*2 -> 0 | P36: =E36*1 -> #VALUE! | Q36: =F36*2 -> #VALUE! | R36: =G36*1 -> #VALUE! | S36: =H36*2 -> #VALUE! | T36: =I36*1 -> #VALUE! | U36: =J36*2 -> #VALUE! | V36: =K36*1 -> #VALUE! | W36: =L36*2 -> #VALUE! | X36: =M36*1 -> #VALUE! | Y36: =N36*2 -> #VALUE! | Z36: =IF(O36>=10,MID(O36,1,1)+MID(O36,2,1),O36) -> 0 | AA36: =IF(P36>=10,MID(P36,1,1)+MID(P36,2,1),P36) -> #VALUE! | AB36: =IF(Q36>=10,MID(Q36,1,1)+MID(Q36,2,1),Q36) -> #VALUE! | AC36: =IF(R36>=10,MID(R36,1,1)+MID(R36,2,1),R36) -> #VALUE! | AD36: =IF(S36>=10,MID(S36,1,1)+MID(S36,2,1),S36) -> #VALUE! | AE36: =IF(T36>=10,MID(T36,1,1)+MID(T36,2,1),T36) -> #VALUE! | AF36: =IF(U36>=10,MID(U36,1,1)+MID(U36,2,1),U36) -> #VALUE! | AG36: =IF(V36>=10,MID(V36,1,1)+MID(V36,2,1),V36) -> #VALUE! | ... AJ36: =IF(Y36>=10,MID(Y36,1,1)+MID(Y36,2,1),Y36) -> #VALUE! | AK36: =SUM(Z36:AJ36) -> #VALUE! | AL36: =ROUNDUP(AK36,-1) -> #VALUE! | AM36: =AL36-AK36 -> #VALUE! | AN36: =IF(ISBLANK(Wagenliste!B36),0,AM36-C36) -> 0 | AO36: =IF(ISBLANK(Wagenliste!B36),"",IF(LEN(Wagenliste!B36)>12,0,1))
B41: Letzte Wagennummer | D41: 1.St. | E41: 2.St. | F41: 3.St. | G41: 4.St.
B42: {=INDEX(Wagenliste!B:B,MAX(ISNUMBER(Wagenliste!B7:F36)*ROW(Wagenliste!B7:F36)))} -> 378079297701 | D42: =MID(B42,9,1) -> 7 | E42: =MID(B42,10,1) -> 7 | F42: =MID(B42,11,1) -> 0 | G42: =MID(B42,12,1) -> 1
B44: =IF(ISERROR(C7)=TRUE,1,2) -> 2
B46: Erste Wagennummer | D46: 1.St. | E46: 2.St. | F46: 3.St.
B47: =Wagenliste!B7 -> 378078308871 | D47: =MID(B47,9,1) -> 8 | E47: =MID(B47,10,1) -> 8 | F47: =MID(B47,11,1) -> 7
